[W 2024-06-05 13:45:36.174 ServerApp] jupyter_server_terminals | error adding extension (enabled: True): Jupyter Server Terminals requires Jupyter Server 2.0+
    Traceback (most recent call last):
      File "/home/users/pete_nut/miniconda3/envs/petes_env/lib/python3.8/site-packages/jupyter_server/extension/manager.py", line 320, in add_extension
        extpkg = ExtensionPackage(name=extension_name, enabled=enabled)
      File "/home/users/pete_nut/miniconda3/envs/petes_env/lib/python3.8/site-packages/jupyter_server/extension/manager.py", line 166, in __init__
        super().__init__(*args, **kwargs)
      File "/home/users/pete_nut/miniconda3/envs/petes_env/lib/python3.8/site-packages/traitlets/traitlets.py", line 1371, in __init__
        value = self._traits[key]._cross_validate(self, getattr(self, key))
      File "/home/users/pete_nut/miniconda3/envs/petes_env/lib/python3.8/site-packages/traitlets/traitlets.py", line 732, in _cross_validate
        value = obj._trait_validators[self.name](obj, proposal)
      File "/home/users/pete_nut/miniconda3/envs/petes_env/lib/python3.8/site-packages/traitlets/traitlets.py", line 1243, in __call__
        return self.func(*args, **kwargs)
      File "/home/users/pete_nut/miniconda3/envs/petes_env/lib/python3.8/site-packages/jupyter_server/extension/manager.py", line 175, in _validate_name
        self._module, self._metadata = get_metadata(name)
      File "/home/users/pete_nut/miniconda3/envs/petes_env/lib/python3.8/site-packages/jupyter_server/extension/utils.py", line 60, in get_metadata
        module = importlib.import_module(package_name)
      File "/home/users/pete_nut/miniconda3/envs/petes_env/lib/python3.8/importlib/__init__.py", line 127, in import_module
        return _bootstrap._gcd_import(name[level:], package, level)
      File "<frozen importlib._bootstrap>", line 1014, in _gcd_import
      File "<frozen importlib._bootstrap>", line 991, in _find_and_load
      File "<frozen importlib._bootstrap>", line 975, in _find_and_load_unlocked
      File "<frozen importlib._bootstrap>", line 671, in _load_unlocked
      File "<frozen importlib._bootstrap_external>", line 843, in exec_module
      File "<frozen importlib._bootstrap>", line 219, in _call_with_frames_removed
      File "/home/users/pete_nut/miniconda3/envs/petes_env/lib/python3.8/site-packages/jupyter_server_terminals/__init__.py", line 9, in <module>
        raise RuntimeError("Jupyter Server Terminals requires Jupyter Server 2.0+")
    RuntimeError: Jupyter Server Terminals requires Jupyter Server 2.0+
[I 2024-06-05 13:45:36.337 ServerApp] jupyter_lsp | extension was successfully linked.
[I 2024-06-05 13:45:36.337 ServerApp] jupyter_resource_usage | extension was successfully linked.
[I 2024-06-05 13:45:36.342 ServerApp] jupyter_server_fileid | extension was successfully linked.
[I 2024-06-05 13:45:36.346 ServerApp] jupyter_server_ydoc | extension was successfully linked.
[I 2024-06-05 13:45:36.352 ServerApp] jupyterlab | extension was successfully linked.
[I 2024-06-05 13:45:36.356 ServerApp] nbclassic | extension was successfully linked.
[I 2024-06-05 13:45:37.239 ServerApp] nbresuse | extension was found and enabled by notebook_shim. Consider moving the extension to Jupyter Server's extension paths.
[I 2024-06-05 13:45:37.239 ServerApp] nbresuse | extension was successfully linked.
[I 2024-06-05 13:45:37.239 ServerApp] notebook_shim | extension was successfully linked.
[I 2024-06-05 13:45:37.323 ServerApp] notebook_shim | extension was successfully loaded.
[I 2024-06-05 13:45:37.325 ServerApp] jupyter_lsp | extension was successfully loaded.
[I 2024-06-05 13:45:37.326 ServerApp] jupyter_resource_usage | extension was successfully loaded.
[I 2024-06-05 13:45:37.326 FileIdExtension] Configured File ID manager: ArbitraryFileIdManager
[I 2024-06-05 13:45:37.327 FileIdExtension] ArbitraryFileIdManager : Configured root dir: /home/users/pete_nut/shipping_ccf
[I 2024-06-05 13:45:37.327 FileIdExtension] ArbitraryFileIdManager : Configured database path: /home/users/pete_nut/.local/share/jupyter/file_id_manager.db
[I 2024-06-05 13:45:37.329 FileIdExtension] ArbitraryFileIdManager : Successfully connected to database file.
[I 2024-06-05 13:45:37.329 FileIdExtension] ArbitraryFileIdManager : Creating File ID tables and indices with journal_mode = DELETE
[I 2024-06-05 13:45:37.336 ServerApp] jupyter_server_fileid | extension was successfully loaded.
[I 2024-06-05 13:45:37.337 ServerApp] jupyter_server_ydoc | extension was successfully loaded.
[I 2024-06-05 13:45:37.346 LabApp] JupyterLab extension loaded from /home/users/pete_nut/miniconda3/envs/petes_env/lib/python3.8/site-packages/jupyterlab
[I 2024-06-05 13:45:37.346 LabApp] JupyterLab application directory is /home/users/pete_nut/miniconda3/envs/petes_env/share/jupyter/lab
[I 2024-06-05 13:45:37.349 ServerApp] jupyterlab | extension was successfully loaded.
[I 2024-06-05 13:45:37.362 ServerApp] nbclassic | extension was successfully loaded.
[W 2024-06-05 13:45:37.362 ServerApp] nbresuse | extension failed loading with message: Duplicated timeseries in CollectorRegistry: {'total_memory_usage'}
[E 2024-06-05 13:45:37.362 ServerApp] nbresuse | stack trace
    Traceback (most recent call last):
      File "/home/users/pete_nut/miniconda3/envs/petes_env/lib/python3.8/site-packages/jupyter_server/extension/manager.py", line 355, in load_extension
        extension.load_all_points(self.serverapp)
      File "/home/users/pete_nut/miniconda3/envs/petes_env/lib/python3.8/site-packages/jupyter_server/extension/manager.py", line 229, in load_all_points
        return [self.load_point(point_name, serverapp) for point_name in self.extension_points]
      File "/home/users/pete_nut/miniconda3/envs/petes_env/lib/python3.8/site-packages/jupyter_server/extension/manager.py", line 229, in <listcomp>
        return [self.load_point(point_name, serverapp) for point_name in self.extension_points]
      File "/home/users/pete_nut/miniconda3/envs/petes_env/lib/python3.8/site-packages/jupyter_server/extension/manager.py", line 222, in load_point
        return point.load(serverapp)
      File "/home/users/pete_nut/miniconda3/envs/petes_env/lib/python3.8/site-packages/jupyter_server/extension/manager.py", line 148, in load
        return loader(serverapp)
      File "/home/users/pete_nut/miniconda3/envs/petes_env/lib/python3.8/site-packages/nbresuse/__init__.py", line 49, in load_jupyter_server_extension
        PrometheusHandler(PSUtilMetricsLoader(nbapp)), 1000
      File "/home/users/pete_nut/miniconda3/envs/petes_env/lib/python3.8/site-packages/nbresuse/prometheus.py", line 25, in __init__
        gauge = Gauge(phrase, "counter for " + phrase.replace("_", " "), [])
      File "/home/users/pete_nut/miniconda3/envs/petes_env/lib/python3.8/site-packages/prometheus_client/metrics.py", line 378, in __init__
        super().__init__(
      File "/home/users/pete_nut/miniconda3/envs/petes_env/lib/python3.8/site-packages/prometheus_client/metrics.py", line 155, in __init__
        registry.register(self)
      File "/home/users/pete_nut/miniconda3/envs/petes_env/lib/python3.8/site-packages/prometheus_client/registry.py", line 43, in register
        raise ValueError(
    ValueError: Duplicated timeseries in CollectorRegistry: {'total_memory_usage'}
[I 2024-06-05 13:45:37.368 ServerApp] Serving notebooks from local directory: /home/users/pete_nut/shipping_ccf
[I 2024-06-05 13:45:37.368 ServerApp] Jupyter Server 1.24.0 is running at:
[I 2024-06-05 13:45:37.368 ServerApp] http://localhost:8888/lab?token=20d807fd2491400da1be77342bfe418fb9cde5101331d1ac
[I 2024-06-05 13:45:37.368 ServerApp]  or http://127.0.0.1:8888/lab?token=20d807fd2491400da1be77342bfe418fb9cde5101331d1ac
[I 2024-06-05 13:45:37.368 ServerApp] Use Control-C to stop this server and shut down all kernels (twice to skip confirmation).
[C 2024-06-05 13:45:37.380 ServerApp] 
    
    To access the server, open this file in a browser:
        file:///home/users/pete_nut/.local/share/jupyter/runtime/jpserver-48880-open.html
    Or copy and paste one of these URLs:
        http://localhost:8888/lab?token=20d807fd2491400da1be77342bfe418fb9cde5101331d1ac
     or http://127.0.0.1:8888/lab?token=20d807fd2491400da1be77342bfe418fb9cde5101331d1ac
[I 2024-06-05 13:45:37.426 ServerApp] Skipped non-installed server(s): bash-language-server, dockerfile-language-server-nodejs, javascript-typescript-langserver, jedi-language-server, julia-language-server, pyright, python-language-server, python-lsp-server, r-languageserver, sql-language-server, texlab, typescript-language-server, unified-language-server, vscode-css-languageserver-bin, vscode-html-languageserver-bin, vscode-json-languageserver-bin, yaml-language-server
[I 2024-06-05 14:03:07.228 ServerApp] 302 GET /?token=[secret] (127.0.0.1) 0.52ms
[W 2024-06-05 14:03:09.085 ServerApp] 404 GET /api/me?1717592588436 (127.0.0.1) 26.55ms referer=http://localhost:8888/lab
[W 2024-06-05 14:03:10.583 LabApp] Could not determine jupyterlab build status without nodejs
[I 2024-06-05 14:06:36.009 ServerApp] Creating new directory in 
[I 2024-06-05 14:07:19.125 ServerApp] Kernel started: 34c6bd69-8082-4544-88be-2a2f987f233e
[W 2024-06-05 14:07:20.305 ServerApp] Could not destroy zmq context for <jupyter_client.asynchronous.client.AsyncKernelClient object at 0x7fc30190a940>
[I 2024-06-05 14:08:21.010 ServerApp] Kernel shutdown: 34c6bd69-8082-4544-88be-2a2f987f233e
[W 2024-06-05 14:08:23.690 ServerApp] delete /preprocessing/collocate_ERA5.ipynb
[I 2024-06-05 14:12:57.955 ServerApp] Kernel started: 8c309bf5-1209-4b62-be17-5d40e31a8fbc
/home/users/pete_nut/miniconda3/envs/petes_env/lib/python3.8/json/encoder.py:257: UserWarning: date_default is deprecated since jupyter_client 7.0.0. Use jupyter_client.jsonutil.json_default.
  return _iterencode(o, 0)
[W 2024-06-05 14:12:58.990 ServerApp] Could not destroy zmq context for <jupyter_client.asynchronous.client.AsyncKernelClient object at 0x7fc301b21700>
[I 2024-06-05 14:13:07.225 ServerApp] Creating new file in /preprocessing
[I 2024-06-05 14:13:32.244 ServerApp] Saving file at /preprocessing/subset_EIS.py
[I 2024-06-05 14:13:40.111 ServerApp] Kernel shutdown: 8c309bf5-1209-4b62-be17-5d40e31a8fbc
[W 2024-06-05 14:13:47.826 ServerApp] delete /preprocessing/subset_EIS.ipynb
2015
EIS_2015.nc
2016
EIS_2016.nc
[I 2024-06-05 14:25:08.888 ServerApp] Kernel started: bebc7203-01f9-4768-b72c-1b0f8e7f008f
[W 2024-06-05 14:25:09.947 ServerApp] Could not destroy zmq context for <jupyter_client.asynchronous.client.AsyncKernelClient object at 0x7fc301a6d190>
[I 2024-06-05 14:25:29.830 ServerApp] Saving file at /organise_regressors.ipynb
[W 2024-06-05 14:48:10.029 ServerApp] WebSocket ping timeout after 119981 ms.
[I 2024-06-05 14:48:15.031 ServerApp] Starting buffering for bebc7203-01f9-4768-b72c-1b0f8e7f008f:be19c9d5-76de-4583-af57-ea6ba37a39e4
[C 2024-06-06 08:06:58.446 ServerApp] received signal 15, stopping
[I 2024-06-06 08:06:59.187 ServerApp] Shutting down 8 extensions
[I 2024-06-06 08:06:59.188 ServerApp] AsyncIOLoopKernelRestarter: restarting kernel (1/5), keep random ports
[I 2024-06-06 08:06:59.266 ServerApp] Shutting down 1 kernel
[I 2024-06-06 08:06:59.355 ServerApp] Kernel shutdown: bebc7203-01f9-4768-b72c-1b0f8e7f008f
[E 2024-06-06 08:06:59.459 ServerApp] Exception in callback functools.partial(<bound method IOLoop._discard_future_result of <tornado.platform.asyncio.AsyncIOMainLoop object at 0x7fc3825a6fa0>>, <Task finished name='Task-87238' coro=<ServerApp._stop() done, defined at /home/users/pete_nut/miniconda3/envs/petes_env/lib/python3.8/site-packages/jupyter_server/serverapp.py:2777> exception=InvalidStateError('Exception is not set.')>)
    Traceback (most recent call last):
      File "/home/users/pete_nut/miniconda3/envs/petes_env/lib/python3.8/site-packages/tornado/ioloop.py", line 741, in _run_callback
        ret = callback()
      File "/home/users/pete_nut/miniconda3/envs/petes_env/lib/python3.8/site-packages/tornado/ioloop.py", line 765, in _discard_future_result
        future.result()
      File "/home/users/pete_nut/miniconda3/envs/petes_env/lib/python3.8/asyncio/futures.py", line 178, in result
        raise self._exception
      File "/home/users/pete_nut/miniconda3/envs/petes_env/lib/python3.8/asyncio/tasks.py", line 282, in __step
        result = coro.throw(exc)
      File "/home/users/pete_nut/miniconda3/envs/petes_env/lib/python3.8/site-packages/jupyter_server/serverapp.py", line 2779, in _stop
        await self._cleanup()
      File "/home/users/pete_nut/miniconda3/envs/petes_env/lib/python3.8/site-packages/jupyter_server/serverapp.py", line 2748, in _cleanup
        await self.cleanup_kernels()
      File "/home/users/pete_nut/miniconda3/envs/petes_env/lib/python3.8/site-packages/jupyter_server/serverapp.py", line 2443, in cleanup_kernels
        await run_sync_in_loop(self.kernel_manager.shutdown_all())
      File "/home/users/pete_nut/miniconda3/envs/petes_env/lib/python3.8/site-packages/jupyter_server/utils.py", line 259, in run_sync_in_loop
        return await maybe_async
      File "/home/users/pete_nut/miniconda3/envs/petes_env/lib/python3.8/site-packages/jupyter_client/multikernelmanager.py", line 313, in _async_shutdown_all
        await asyncio.gather(*futs)
      File "/home/users/pete_nut/miniconda3/envs/petes_env/lib/python3.8/asyncio/tasks.py", line 349, in __wakeup
        future.result()
      File "/home/users/pete_nut/miniconda3/envs/petes_env/lib/python3.8/asyncio/tasks.py", line 280, in __step
        result = coro.send(None)
      File "/home/users/pete_nut/miniconda3/envs/petes_env/lib/python3.8/site-packages/jupyter_client/utils.py", line 38, in ensure_async
        return await obj
      File "/home/users/pete_nut/miniconda3/envs/petes_env/lib/python3.8/site-packages/jupyter_server/services/kernels/kernelmanager.py", line 671, in shutdown_kernel
        return await self.pinned_superclass.shutdown_kernel(
      File "/home/users/pete_nut/miniconda3/envs/petes_env/lib/python3.8/site-packages/jupyter_client/multikernelmanager.py", line 264, in _async_shutdown_kernel
        if not km.ready.cancelled() and km.ready.exception():
    asyncio.exceptions.InvalidStateError: Exception is not set.
[W 2024-06-06 10:44:46.271 ServerApp] jupyter_server_terminals | error adding extension (enabled: True): Jupyter Server Terminals requires Jupyter Server 2.0+
    Traceback (most recent call last):
      File "/home/users/pete_nut/miniconda3/envs/petes_env/lib/python3.8/site-packages/jupyter_server/extension/manager.py", line 320, in add_extension
        extpkg = ExtensionPackage(name=extension_name, enabled=enabled)
      File "/home/users/pete_nut/miniconda3/envs/petes_env/lib/python3.8/site-packages/jupyter_server/extension/manager.py", line 166, in __init__
        super().__init__(*args, **kwargs)
      File "/home/users/pete_nut/miniconda3/envs/petes_env/lib/python3.8/site-packages/traitlets/traitlets.py", line 1371, in __init__
        value = self._traits[key]._cross_validate(self, getattr(self, key))
      File "/home/users/pete_nut/miniconda3/envs/petes_env/lib/python3.8/site-packages/traitlets/traitlets.py", line 732, in _cross_validate
        value = obj._trait_validators[self.name](obj, proposal)
      File "/home/users/pete_nut/miniconda3/envs/petes_env/lib/python3.8/site-packages/traitlets/traitlets.py", line 1243, in __call__
        return self.func(*args, **kwargs)
      File "/home/users/pete_nut/miniconda3/envs/petes_env/lib/python3.8/site-packages/jupyter_server/extension/manager.py", line 175, in _validate_name
        self._module, self._metadata = get_metadata(name)
      File "/home/users/pete_nut/miniconda3/envs/petes_env/lib/python3.8/site-packages/jupyter_server/extension/utils.py", line 60, in get_metadata
        module = importlib.import_module(package_name)
      File "/home/users/pete_nut/miniconda3/envs/petes_env/lib/python3.8/importlib/__init__.py", line 127, in import_module
        return _bootstrap._gcd_import(name[level:], package, level)
      File "<frozen importlib._bootstrap>", line 1014, in _gcd_import
      File "<frozen importlib._bootstrap>", line 991, in _find_and_load
      File "<frozen importlib._bootstrap>", line 975, in _find_and_load_unlocked
      File "<frozen importlib._bootstrap>", line 671, in _load_unlocked
      File "<frozen importlib._bootstrap_external>", line 843, in exec_module
      File "<frozen importlib._bootstrap>", line 219, in _call_with_frames_removed
      File "/home/users/pete_nut/miniconda3/envs/petes_env/lib/python3.8/site-packages/jupyter_server_terminals/__init__.py", line 9, in <module>
        raise RuntimeError("Jupyter Server Terminals requires Jupyter Server 2.0+")
    RuntimeError: Jupyter Server Terminals requires Jupyter Server 2.0+
[I 2024-06-06 10:44:46.789 ServerApp] jupyter_lsp | extension was successfully linked.
[I 2024-06-06 10:44:46.789 ServerApp] jupyter_resource_usage | extension was successfully linked.
[I 2024-06-06 10:44:46.795 ServerApp] jupyter_server_fileid | extension was successfully linked.
[I 2024-06-06 10:44:46.803 ServerApp] jupyter_server_ydoc | extension was successfully linked.
[I 2024-06-06 10:44:46.810 ServerApp] jupyterlab | extension was successfully linked.
[I 2024-06-06 10:44:46.820 ServerApp] nbclassic | extension was successfully linked.
[I 2024-06-06 10:44:48.459 ServerApp] nbresuse | extension was found and enabled by notebook_shim. Consider moving the extension to Jupyter Server's extension paths.
[I 2024-06-06 10:44:48.459 ServerApp] nbresuse | extension was successfully linked.
[I 2024-06-06 10:44:48.459 ServerApp] notebook_shim | extension was successfully linked.
[I 2024-06-06 10:44:48.576 ServerApp] notebook_shim | extension was successfully loaded.
[I 2024-06-06 10:44:48.578 ServerApp] jupyter_lsp | extension was successfully loaded.
[I 2024-06-06 10:44:48.579 ServerApp] jupyter_resource_usage | extension was successfully loaded.
[I 2024-06-06 10:44:48.579 FileIdExtension] Configured File ID manager: ArbitraryFileIdManager
[I 2024-06-06 10:44:48.579 FileIdExtension] ArbitraryFileIdManager : Configured root dir: /home/users/pete_nut/shipping_ccf
[I 2024-06-06 10:44:48.579 FileIdExtension] ArbitraryFileIdManager : Configured database path: /home/users/pete_nut/.local/share/jupyter/file_id_manager.db
[I 2024-06-06 10:44:48.581 FileIdExtension] ArbitraryFileIdManager : Successfully connected to database file.
[I 2024-06-06 10:44:48.581 FileIdExtension] ArbitraryFileIdManager : Creating File ID tables and indices with journal_mode = DELETE
[I 2024-06-06 10:44:48.602 ServerApp] jupyter_server_fileid | extension was successfully loaded.
[I 2024-06-06 10:44:48.602 ServerApp] jupyter_server_ydoc | extension was successfully loaded.
[I 2024-06-06 10:44:48.632 LabApp] JupyterLab extension loaded from /home/users/pete_nut/miniconda3/envs/petes_env/lib/python3.8/site-packages/jupyterlab
[I 2024-06-06 10:44:48.632 LabApp] JupyterLab application directory is /home/users/pete_nut/miniconda3/envs/petes_env/share/jupyter/lab
[I 2024-06-06 10:44:48.637 ServerApp] jupyterlab | extension was successfully loaded.
[I 2024-06-06 10:44:48.682 ServerApp] nbclassic | extension was successfully loaded.
[W 2024-06-06 10:44:48.682 ServerApp] nbresuse | extension failed loading with message: Duplicated timeseries in CollectorRegistry: {'total_memory_usage'}
[E 2024-06-06 10:44:48.682 ServerApp] nbresuse | stack trace
    Traceback (most recent call last):
      File "/home/users/pete_nut/miniconda3/envs/petes_env/lib/python3.8/site-packages/jupyter_server/extension/manager.py", line 355, in load_extension
        extension.load_all_points(self.serverapp)
      File "/home/users/pete_nut/miniconda3/envs/petes_env/lib/python3.8/site-packages/jupyter_server/extension/manager.py", line 229, in load_all_points
        return [self.load_point(point_name, serverapp) for point_name in self.extension_points]
      File "/home/users/pete_nut/miniconda3/envs/petes_env/lib/python3.8/site-packages/jupyter_server/extension/manager.py", line 229, in <listcomp>
        return [self.load_point(point_name, serverapp) for point_name in self.extension_points]
      File "/home/users/pete_nut/miniconda3/envs/petes_env/lib/python3.8/site-packages/jupyter_server/extension/manager.py", line 222, in load_point
        return point.load(serverapp)
      File "/home/users/pete_nut/miniconda3/envs/petes_env/lib/python3.8/site-packages/jupyter_server/extension/manager.py", line 148, in load
        return loader(serverapp)
      File "/home/users/pete_nut/miniconda3/envs/petes_env/lib/python3.8/site-packages/nbresuse/__init__.py", line 49, in load_jupyter_server_extension
        PrometheusHandler(PSUtilMetricsLoader(nbapp)), 1000
      File "/home/users/pete_nut/miniconda3/envs/petes_env/lib/python3.8/site-packages/nbresuse/prometheus.py", line 25, in __init__
        gauge = Gauge(phrase, "counter for " + phrase.replace("_", " "), [])
      File "/home/users/pete_nut/miniconda3/envs/petes_env/lib/python3.8/site-packages/prometheus_client/metrics.py", line 378, in __init__
        super().__init__(
      File "/home/users/pete_nut/miniconda3/envs/petes_env/lib/python3.8/site-packages/prometheus_client/metrics.py", line 155, in __init__
        registry.register(self)
      File "/home/users/pete_nut/miniconda3/envs/petes_env/lib/python3.8/site-packages/prometheus_client/registry.py", line 43, in register
        raise ValueError(
    ValueError: Duplicated timeseries in CollectorRegistry: {'total_memory_usage'}
[I 2024-06-06 10:44:48.692 ServerApp] Serving notebooks from local directory: /home/users/pete_nut/shipping_ccf
[I 2024-06-06 10:44:48.692 ServerApp] Jupyter Server 1.24.0 is running at:
[I 2024-06-06 10:44:48.692 ServerApp] http://localhost:8888/lab?token=43c45ceaaaf6ae7b6bf535dbe9a875bf767c4e11d3be5292
[I 2024-06-06 10:44:48.692 ServerApp]  or http://127.0.0.1:8888/lab?token=43c45ceaaaf6ae7b6bf535dbe9a875bf767c4e11d3be5292
[I 2024-06-06 10:44:48.692 ServerApp] Use Control-C to stop this server and shut down all kernels (twice to skip confirmation).
[C 2024-06-06 10:44:48.724 ServerApp] 
    
    To access the server, open this file in a browser:
        file:///home/users/pete_nut/.local/share/jupyter/runtime/jpserver-19976-open.html
    Or copy and paste one of these URLs:
        http://localhost:8888/lab?token=43c45ceaaaf6ae7b6bf535dbe9a875bf767c4e11d3be5292
     or http://127.0.0.1:8888/lab?token=43c45ceaaaf6ae7b6bf535dbe9a875bf767c4e11d3be5292
[I 2024-06-06 10:44:48.877 ServerApp] Skipped non-installed server(s): bash-language-server, dockerfile-language-server-nodejs, javascript-typescript-langserver, jedi-language-server, julia-language-server, pyright, python-language-server, python-lsp-server, r-languageserver, sql-language-server, texlab, typescript-language-server, unified-language-server, vscode-css-languageserver-bin, vscode-html-languageserver-bin, vscode-json-languageserver-bin, yaml-language-server
[I 2024-06-06 10:45:12.166 ServerApp] 302 GET /?token=[secret] (127.0.0.1) 0.56ms
[W 2024-06-06 10:45:14.084 ServerApp] 404 GET /api/me?1717667113109 (127.0.0.1) 53.60ms referer=http://localhost:8888/lab
[W 2024-06-06 10:45:16.275 LabApp] Could not determine jupyterlab build status without nodejs
[I 2024-06-06 10:45:18.989 ServerApp] Kernel started: 0e85e0b2-7422-480b-be44-96e0f887ba3f
[W 2024-06-06 10:45:20.213 ServerApp] Could not destroy zmq context for <jupyter_client.asynchronous.client.AsyncKernelClient object at 0x7f047b98bb80>
[I 2024-06-06 10:47:18.677 ServerApp] Saving file at /organise_regressors.ipynb
[I 2024-06-06 10:49:19.122 ServerApp] Saving file at /organise_regressors.ipynb
[I 2024-06-06 10:51:21.857 ServerApp] Saving file at /organise_regressors.ipynb
[I 2024-06-06 10:57:22.028 ServerApp] Saving file at /organise_regressors.ipynb
[I 2024-06-06 10:59:22.195 ServerApp] Saving file at /organise_regressors.ipynb
[I 2024-06-06 11:01:22.358 ServerApp] Saving file at /organise_regressors.ipynb
[I 2024-06-06 11:03:22.491 ServerApp] Saving file at /organise_regressors.ipynb
[I 2024-06-06 11:05:22.679 ServerApp] Saving file at /organise_regressors.ipynb
[I 2024-06-06 11:07:22.829 ServerApp] Saving file at /organise_regressors.ipynb
[W 2024-06-06 11:13:21.117 ServerApp] WebSocket ping timeout after 119988 ms.
[W 2024-06-06 11:13:21.139 ServerApp] WebSocket ping timeout after 119987 ms.
[I 2024-06-06 11:13:26.140 ServerApp] Starting buffering for 0e85e0b2-7422-480b-be44-96e0f887ba3f:c5f0b9e6-0e36-4cc7-bfcc-e8c6d1a549b3
[I 2024-06-06 11:16:01.080 ServerApp] Saving file at /organise_regressors.ipynb
[I 2024-06-06 11:18:01.258 ServerApp] Saving file at /organise_regressors.ipynb
[I 2024-06-06 11:20:01.427 ServerApp] Saving file at /organise_regressors.ipynb
[I 2024-06-06 11:22:01.578 ServerApp] Saving file at /organise_regressors.ipynb
[I 2024-06-06 11:24:02.173 ServerApp] Saving file at /organise_regressors.ipynb
[I 2024-06-06 11:26:03.220 ServerApp] Saving file at /organise_regressors.ipynb
[I 2024-06-06 11:30:10.478 ServerApp] Saving file at /organise_regressors.ipynb
[I 2024-06-06 11:31:07.801 ServerApp] Saving file at /organise_regressors.ipynb
[I 2024-06-06 11:31:13.225 ServerApp] Starting buffering for 0e85e0b2-7422-480b-be44-96e0f887ba3f:4de0d32c-0351-4af5-9adf-4e24ddb090b2
[W 2024-06-06 11:31:14.266 ServerApp] 404 GET /api/me?1717669874234 (127.0.0.1) 3.08ms referer=http://localhost:8888/lab
[W 2024-06-06 11:31:15.860 LabApp] Could not determine jupyterlab build status without nodejs
/home/users/pete_nut/miniconda3/envs/petes_env/lib/python3.8/json/encoder.py:257: UserWarning: date_default is deprecated since jupyter_client 7.0.0. Use jupyter_client.jsonutil.json_default.
  return _iterencode(o, 0)
[W 2024-06-06 11:31:18.395 ServerApp] Could not destroy zmq context for <jupyter_client.asynchronous.client.AsyncKernelClient object at 0x7f047b04faf0>
[I 2024-06-06 11:31:18.404 ServerApp] Discarding 2 buffered messages for 0e85e0b2-7422-480b-be44-96e0f887ba3f:4de0d32c-0351-4af5-9adf-4e24ddb090b2
[I 2024-06-06 11:31:28.739 ServerApp] Creating new notebook in /preprocessing
[I 2024-06-06 11:31:31.139 ServerApp] Kernel started: e86ec29d-ac9d-460d-a08a-dbe38f9d8702
[W 2024-06-06 11:31:32.320 ServerApp] Could not destroy zmq context for <jupyter_client.asynchronous.client.AsyncKernelClient object at 0x7f047ba3feb0>
[W 2024-06-06 11:31:49.376 ServerApp] Could not destroy zmq context for <jupyter_client.asynchronous.client.AsyncKernelClient object at 0x7f047b39a550>
[W 2024-06-06 11:31:53.962 ServerApp] Could not destroy zmq context for <jupyter_client.asynchronous.client.AsyncKernelClient object at 0x7f047af44ee0>
[W 2024-06-06 11:32:17.238 ServerApp] Could not destroy zmq context for <jupyter_client.asynchronous.client.AsyncKernelClient object at 0x7f047b39aa60>
[W 2024-06-06 11:32:18.537 ServerApp] Could not destroy zmq context for <jupyter_client.asynchronous.client.AsyncKernelClient object at 0x7f047b04cbb0>
[I 2024-06-06 11:32:32.443 ServerApp] Saving file at /preprocessing/Untitled.ipynb
[W 2024-06-06 11:32:34.474 ServerApp] Could not destroy zmq context for <jupyter_client.asynchronous.client.AsyncKernelClient object at 0x7f047b987d30>
[W 2024-06-06 11:32:47.443 ServerApp] Could not destroy zmq context for <jupyter_client.asynchronous.client.AsyncKernelClient object at 0x7f047b03f0a0>
[W 2024-06-06 11:32:59.063 ServerApp] Could not destroy zmq context for <jupyter_client.asynchronous.client.AsyncKernelClient object at 0x7f047b94de20>
[W 2024-06-06 11:33:04.301 ServerApp] Could not destroy zmq context for <jupyter_client.asynchronous.client.AsyncKernelClient object at 0x7f047b39a3a0>
[W 2024-06-06 11:33:42.380 ServerApp] Could not destroy zmq context for <jupyter_client.asynchronous.client.AsyncKernelClient object at 0x7f047b04b400>
[W 2024-06-06 11:33:46.168 ServerApp] Could not destroy zmq context for <jupyter_client.asynchronous.client.AsyncKernelClient object at 0x7f047af4f190>
[I 2024-06-06 11:34:32.575 ServerApp] Saving file at /preprocessing/cleanup_nulldates.ipynb
[W 2024-06-06 11:34:58.235 ServerApp] Could not destroy zmq context for <jupyter_client.asynchronous.client.AsyncKernelClient object at 0x7f047af49310>
[W 2024-06-06 11:35:07.030 ServerApp] Could not destroy zmq context for <jupyter_client.asynchronous.client.AsyncKernelClient object at 0x7f047af49310>
[W 2024-06-06 11:35:53.177 ServerApp] Could not destroy zmq context for <jupyter_client.asynchronous.client.AsyncKernelClient object at 0x7f047bae8ac0>
[W 2024-06-06 11:35:56.281 ServerApp] Could not destroy zmq context for <jupyter_client.asynchronous.client.AsyncKernelClient object at 0x7f047af47520>
[I 2024-06-06 11:36:32.709 ServerApp] Saving file at /preprocessing/cleanup_nulldates.ipynb
[I 2024-06-06 11:38:32.816 ServerApp] Saving file at /preprocessing/cleanup_nulldates.ipynb
[I 2024-06-06 11:40:33.017 ServerApp] Saving file at /preprocessing/cleanup_nulldates.ipynb
[I 2024-06-06 11:42:33.172 ServerApp] Saving file at /preprocessing/cleanup_nulldates.ipynb
[I 2024-06-06 11:44:33.341 ServerApp] Saving file at /preprocessing/cleanup_nulldates.ipynb
[I 2024-06-06 11:46:33.601 ServerApp] Saving file at /preprocessing/cleanup_nulldates.ipynb
[I 2024-06-06 11:48:33.762 ServerApp] Saving file at /preprocessing/cleanup_nulldates.ipynb
[I 2024-06-06 11:50:33.927 ServerApp] Saving file at /preprocessing/cleanup_nulldates.ipynb
[I 2024-06-06 11:52:34.071 ServerApp] Saving file at /preprocessing/cleanup_nulldates.ipynb
[I 2024-06-06 11:52:45.838 ServerApp] Saving file at /preprocessing/cleanup_nulldates.ipynb
[W 2024-06-06 11:52:48.446 ServerApp] Could not destroy zmq context for <jupyter_client.asynchronous.client.AsyncKernelClient object at 0x7f047af4f190>
[I 2024-06-06 11:53:17.853 ServerApp] Saving file at /organise_regressors.ipynb
[I 2024-06-06 11:55:58.259 ServerApp] Saving file at /organise_regressors.ipynb
[I 2024-06-06 11:57:58.450 ServerApp] Saving file at /organise_regressors.ipynb
[I 2024-06-06 12:01:58.736 ServerApp] Saving file at /organise_regressors.ipynb
[W 2024-06-06 12:03:16.798 ServerApp] Could not destroy zmq context for <jupyter_client.asynchronous.client.AsyncKernelClient object at 0x7f047b04fdf0>
[I 2024-06-06 12:03:58.902 ServerApp] Saving file at /organise_regressors.ipynb
[I 2024-06-06 12:04:51.186 ServerApp] Saving file at /preprocessing/cleanup_nulldates.ipynb
[W 2024-06-06 12:04:55.680 ServerApp] Could not destroy zmq context for <jupyter_client.asynchronous.client.AsyncKernelClient object at 0x7f047b83f9d0>
[W 2024-06-06 12:05:48.094 ServerApp] Could not destroy zmq context for <jupyter_client.asynchronous.client.AsyncKernelClient object at 0x7f047b04ccd0>
[I 2024-06-06 12:05:49.110 ServerApp] Saving file at /preprocessing/cleanup_nulldates.ipynb
[I 2024-06-06 12:05:59.052 ServerApp] Saving file at /organise_regressors.ipynb
[W 2024-06-06 12:06:13.270 ServerApp] Could not destroy zmq context for <jupyter_client.asynchronous.client.AsyncKernelClient object at 0x7f047b0577f0>
[W 2024-06-06 12:06:58.747 ServerApp] Could not destroy zmq context for <jupyter_client.asynchronous.client.AsyncKernelClient object at 0x7f047b04fdf0>
[I 2024-06-06 12:07:49.195 ServerApp] Saving file at /preprocessing/cleanup_nulldates.ipynb
[I 2024-06-06 12:07:59.190 ServerApp] Saving file at /organise_regressors.ipynb
[I 2024-06-06 12:09:49.313 ServerApp] Saving file at /preprocessing/cleanup_nulldates.ipynb
[I 2024-06-06 12:15:15.991 ServerApp] Saving file at /preprocessing/cleanup_nulldates.ipynb
[I 2024-06-06 12:15:22.852 ServerApp] Saving file at /preprocessing/cleanup_nulldates.ipynb
[W 2024-06-06 12:15:57.046 ServerApp] Could not destroy zmq context for <jupyter_client.asynchronous.client.AsyncKernelClient object at 0x7f047b89cf10>
[I 2024-06-06 12:16:40.647 ServerApp] Saving file at /organise_regressors.ipynb
[I 2024-06-06 12:18:41.095 ServerApp] Saving file at /organise_regressors.ipynb
[I 2024-06-06 12:32:41.346 ServerApp] Saving file at /organise_regressors.ipynb
[I 2024-06-06 12:34:41.647 ServerApp] Saving file at /organise_regressors.ipynb
[I 2024-06-06 12:40:41.895 ServerApp] Saving file at /organise_regressors.ipynb
[W 2024-06-06 12:41:14.428 ServerApp] Could not destroy zmq context for <jupyter_client.asynchronous.client.AsyncKernelClient object at 0x7f047af47a60>
[I 2024-06-06 12:41:29.958 ServerApp] Saving file at /preprocessing/cleanup_nulldates.ipynb
[I 2024-06-06 12:41:56.311 ServerApp] Creating new directory in /preprocessing
[W 2024-06-06 12:42:03.484 ServerApp] delete /preprocessing/Untitled Folder
[I 2024-06-06 12:42:13.958 ServerApp] Creating new file in /preprocessing
[I 2024-06-06 12:42:29.309 ServerApp] Saving file at /preprocessing/untitled.py
[I 2024-06-06 12:42:39.790 ServerApp] Kernel shutdown: e86ec29d-ac9d-460d-a08a-dbe38f9d8702
[W 2024-06-06 12:42:41.302 ServerApp] Could not destroy zmq context for <jupyter_client.asynchronous.client.AsyncKernelClient object at 0x7f047b8622b0>
[W 2024-06-06 12:42:43.038 ServerApp] Could not destroy zmq context for <jupyter_client.asynchronous.client.AsyncKernelClient object at 0x7f047b39a040>
[I 2024-06-06 12:42:44.107 ServerApp] Saving file at /organise_regressors.ipynb
[W 2024-06-06 12:42:44.189 ServerApp] delete /preprocessing/cleanup_nulldates.ipynb
[W 2024-06-06 12:42:44.296 ServerApp] Could not destroy zmq context for <jupyter_client.asynchronous.client.AsyncKernelClient object at 0x7f047af4bf10>
[I 2024-06-06 12:43:14.811 ServerApp] Saving file at /organise_regressors.ipynb
[I 2024-06-06 12:43:48.178 ServerApp] Saving file at /organise_regressors.ipynb
[I 2024-06-06 12:44:37.380 ServerApp] Saving file at /organise_regressors.ipynb
[I 2024-06-06 12:44:55.097 ServerApp] Creating new file in /preprocessing
[I 2024-06-06 12:46:09.497 ServerApp] Saving file at /preprocessing/combine_into_one_dataset.py
[I 2024-06-06 12:46:37.505 ServerApp] Saving file at /organise_regressors.ipynb
[I 2024-06-06 12:46:53.376 ServerApp] Kernel restarted: 0e85e0b2-7422-480b-be44-96e0f887ba3f
[I 2024-06-06 12:46:53.556 ServerApp] Starting buffering for 0e85e0b2-7422-480b-be44-96e0f887ba3f:514faa2b-8d40-40f5-8b69-418bd36c95a7
[I 2024-06-06 12:46:53.607 ServerApp] Restoring connection for 0e85e0b2-7422-480b-be44-96e0f887ba3f:514faa2b-8d40-40f5-8b69-418bd36c95a7
[W 2024-06-06 12:46:54.630 ServerApp] Could not destroy zmq context for <jupyter_client.asynchronous.client.AsyncKernelClient object at 0x7f047b04c310>
[I 2024-06-06 12:48:37.608 ServerApp] Saving file at /organise_regressors.ipynb
[W 2024-06-06 12:51:53.607 ServerApp] WebSocket ping timeout after 119988 ms.
[I 2024-06-06 12:51:58.609 ServerApp] Starting buffering for 0e85e0b2-7422-480b-be44-96e0f887ba3f:514faa2b-8d40-40f5-8b69-418bd36c95a7
[I 2024-06-06 14:10:46.570 ServerApp] Restoring connection for 0e85e0b2-7422-480b-be44-96e0f887ba3f:514faa2b-8d40-40f5-8b69-418bd36c95a7
